Workbook

Sheet Consolidado
A1: CONSOLIDADO DE CHURN E DOWNSELL — 1 linha por cliente x produto
A2: Filtro: STATUS = Churn ou Downsell. Agrupamento: Cliente (col. A original) x Novo_Produto (col. G original). Valores: soma COM SINAL da coluna Variacao (col. D original) — ver aba Notas.
A4: Cliente | B4: Cód. Cliente | C4: Contrato(s) | D4: Produto | E4: Status | F4: Competência(s) | G4: Qtd. linhas origem | H4: Variação total (R$) | I4: Perda (R$ positivo) | J4: % da perda total | K4: Considera no Churn? | L4: Procede? | M4: Trato por CSM? | N4: Motivo do Cancelamento | O4: Motivo do Cancelamento (categoria)
A5: SERIOS AGROPECUARIA LTDA | B5: 30008363 | C5: 30001083 | D5: Agrimanager ERP | E5: Downsell | F5: fev/26; mai/26 | G5: 3 | H5: =SUMIFS(Base_Tratada!$H:$H,Base_Tratada!$A:$A,$A5,Base_Tratada!$G:$G,$D5) -> -16573.14 | I5: =-H5 -> 16573.14 | J5: =IFERROR(I5/$I$67,0) -> 0.15266014 | K5: Sim | L5: Sim | M5: Sim | N5: Troca de ERP | O5: Troca de ERP
A6: CLODOVEU FRANCIOSI IE 133535746 | B6: 30006916 | C6: 30001424 | D6: Agrimanager ERP | E6: Downsell | F6: jun/26 | G6: 1 | H6: =SUMIFS(Base_Tratada!$H:$H,Base_Tratada!$A:$A,$A6,Base_Tratada!$G:$G,$D6) -> -13701.65 | I6: =-H6 -> 13701.65 | J6: =IFERROR(I6/$I$67,0) -> 0.12620999 | K6: Sim | L6: Sim | M6: Sim | N6: Querem eduzir as licenças porque estava “em processo de migração de ERP”. Por isso, solicitou permanecer com apenas 1 licença de cada módulo ativo, além do cancelamento completo do módulo de Recursos Humanos. | O6: troca de ERP
A7: SERRA BONITA SEMENTES S.A. | B7: 30005436 | C7: 30000899 | D7: Agrimanager ERP | E7: Downsell | F7: fev/26; mai/26 | G7: 2 | H7: =SUMIFS(Base_Tratada!$H:$H,Base_Tratada!$A:$A,$A7,Base_Tratada!$G:$G,$D7) -> -6532.98 | I7: =-H7 -> 6532.98 | J7: =IFERROR(I7/$I$67,0) -> 0.06017723 | K7: Sim | L7: Sim | M7: Sim | N7: Venda da empresa | O7: Venda da empresa
A8: LEONARDO LUIZ OSS | B8: 30016958 | C8: 30005248 | D8: My Farm ERP | E8: Downsell | F8: mai/26 | G8: 1 | H8: =SUMIFS(Base_Tratada!$H:$H,Base_Tratada!$A:$A,$A8,Base_Tratada!$G:$G,$D8) -> -4195.79 | I8: =-H8 -> 4195.79 | J8: =IFERROR(I8/$I$67,0) -> 0.038648675 | L8: Sim | M8: Sim | N8: Cancelamento do serviço de BPO | O8: Decisão estratégica / internalização
A9: 3SB PRODUTOS AGRICOLAS S.A. | B9: 30007727 | C9: 30000677 | D9: Agrimanager ERP | E9: Churn | F9: fev/26 | G9: 5 | H9: =SUMIFS(Base_Tratada!$H:$H,Base_Tratada!$A:$A,$A9,Base_Tratada!$G:$G,$D9) -> -4170.46 | I9: =-H9 -> 4170.46 | J9: =IFERROR(I9/$I$67,0) -> 0.038415352 | K9: Sim | L9: Sim | M9: Sim | N9: Cancelamento parcial: falta de integração com outros sistemas, falta de recursos no produto, mudança nas necessidades do cliente e problemas de suporte | O9: Falta de flexibilidade e automação do AGM.
A10: BRUNO SANCHES TORO | B10: 30015024 | C10: 30004006 | D10: Agrimanager ERP | E10: Churn | F10: jun/26 | G10: 3 | H10: =SUMIFS(Base_Tratada!$H:$H,Base_Tratada!$A:$A,$A10,Base_Tratada!$G:$G,$D10) -> -4010.69 | I10: =-H10 -> 4010.69 | J10: =IFERROR(I10/$I$67,0) -> 0.036943663 | K10: Sim | L10: Sim | M10: Sim | N10: Problemas financeiros | O10: Gap funcional / limitação do produto
A11: CLAUDIO AUGUSTO DINIZ - I.E. 13.235.367-9 | B11: 30009772 | C11: 30001556 | D11: Agrimanager ERP | E11: Churn | F11: mai/26 | G11: 2 | H11: =SUMIFS(Base_Tratada!$H:$H,Base_Tratada!$A:$A,$A11,Base_Tratada!$G:$G,$D11) -> -3408.4 | I11: =-H11 -> 3408.4 | J11: =IFERROR(I11/$I$67,0) -> 0.03139579 | K11: Sim | L11: Sim | M11: Sim | N11: Uso restrito a emissão de nota, tornando a operação inviável | O11: Baixa adoção / não uso
A12: RICARDO SILVA ROCHA IE: 11.196.197-1 | B12: 30013024 | C12: 30003254 | D12: Agrimanager ERP | E12: Churn | F12: fev/26 | G12: 2 | H12: =SUMIFS(Base_Tratada!$H:$H,Base_Tratada!$A:$A,$A12,Base_Tratada!$G:$G,$D12) -> -3117.15 | I12: =-H12 -> 3117.15 | J12: =IFERROR(I12/$I$67,0) -> 0.028712999 | L12: Não | M12: Sim | N12: Migração interna para My Farm (Primavera) — receita retida na Aliare | O12: Migração interna de ERP
A13: NATALINO BIGOLIN IE:13.606.182-6 | B13: 30006687 | C13: 30004170 | D13: Aliare Cloud - PR | E13: Churn | F13: mai/26 | G13: 1 | H13: =SUMIFS(Base_Tratada!$H:$H,Base_Tratada!$A:$A,$A13,Base_Tratada!$G:$G,$D13) -> -3046.65 | I13: =-H13 -> 3046.65 | J13: =IFERROR(I13/$I$67,0) -> 0.028063603 | K13: Sim | L13: Sim | M13: Sim | N13: Sem acesso ao banco de dados | O13: Gap funcional / limitação do produto
A14: LUIS HENRIQUE PAZINI E OUTRO - IE - 133440532 | B14: 30018439 | C14: 30006041 | D14: My Farm ERP | E14: Churn | F14: mai/26 | G14: 1 | H14: =SUMIFS(Base_Tratada!$H:$H,Base_Tratada!$A:$A,$A14,Base_Tratada!$G:$G,$D14) -> -2775.55 | I14: =-H14 -> 2775.55 | J14: =IFERROR(I14/$I$67,0) -> 0.02556642 | K14: Sim | L14: Sim | M14: Sim | N14: Não informado pelo cliente, solicitação de cancelamento sem justificativa porém foi encontrados informações sobre insatisfação sobre instabilidade do sistema. | O14: Instabilidade myFarm.
A15: ZORZETTO ASSES. E CONSULTORIA AGRONOMICA LTDA. | B15: 30010916 | C15: 30002254 | D15: Agrimanager ERP | E15: Churn | F15: jun/26 | G15: 2 | H15: =SUMIFS(Base_Tratada!$H:$H,Base_Tratada!$A:$A,$A15,Base_Tratada!$G:$G,$D15) -> -2243.46 | I15: =-H15 -> 2243.46 | J15: =IFERROR(I15/$I$67,0) -> 0.02066518 | K15: Sim | L15: Sim | M15: Sim (outra vertical) | N15: Não informado — tratado pelo CS de Distribuidor Rural | O15: Troca de ERP
A16: OCTAVIANO RAYMUNDO CAMARGO SILVA IE:212.059.354.118 | B16: 30016194 | C16: 30004772 | D16: Agrimanager ERP | E16: Churn | F16: jun/26 | G16: 1 | H16: =SUMIFS(Base_Tratada!$H:$H,Base_Tratada!$A:$A,$A16,Base_Tratada!$G:$G,$D16) -> -2150.61 | I16: =-H16 -> 2150.61 | J16: =IFERROR(I16/$I$67,0) -> 0.019809911 | K16: Sim | L16: Sim | M16: Sim | N16: Falta de mão de obra para operar o sistema | O16: Falta de mão de obra / estrutura
A17: VALQUIRIA MARCELINO FERREIRA ABREU IE: 13.429.008-9 | B17: 30016155 | C17: 30004756 | D17: Agrimanager ERP | E17: Churn | F17: mai/26 | G17: 1 | H17: =SUMIFS(Base_Tratada!$H:$H,Base_Tratada!$A:$A,$A17,Base_Tratada!$G:$G,$D17) -> -2110.81 | I17: =-H17 -> 2110.81 | J17: =IFERROR(I17/$I$67,0) -> 0.019443301 | K17: Sim | L17: Sim | M17: Não localizado | N17: Não informado — sem histórico de tratativas | O17: Troca de ERP
A18: CLODOVEU FRANCIOSI IE 133535746 | B18: 30006916 | C18: 30001424 | D18: Agrimanager Algodoeira | E18: Churn | F18: mar/26 | G18: 1 | H18: =SUMIFS(Base_Tratada!$H:$H,Base_Tratada!$A:$A,$A18,Base_Tratada!$G:$G,$D18) -> -1926.9898 | I18: =-H18 -> 1926.9898 | J18: =IFERROR(I18/$I$67,0) -> 0.017750078 | K18: Sim | L18: Sim | M18: Sim | N18: Troca de ERP | O18: Troca de ERP
A19: SEMENTES TRES PINHEIROS SEEDS LTDA | B19: 30010348 | C19: 30004593 | D19: Aliare Cloud - PR | E19: Churn | F19: jan/26 | G19: 1 | H19: =SUMIFS(Base_Tratada!$H:$H,Base_Tratada!$A:$A,$A19,Base_Tratada!$G:$G,$D19) -> -1875.06 | I19: =-H19 -> 1875.06 | J19: =IFERROR(I19/$I$67,0) -> 0.017271738 | K19: Sim | L19: Sim | M19: Não | N19: Não informado | O19: Troca de ERP
A20: MARCONDES AGROPECUARIA LTDA | B20: 30010824 | C20: 30001946 | D20: Vistra BI - PR | E20: Downsell | F20: fev/26 | G20: 1 | H20: =SUMIFS(Base_Tratada!$H:$H,Base_Tratada!$A:$A,$A20,Base_Tratada!$G:$G,$D20) -> -1865.58 | I20: =-H20 -> 1865.58 | J20: =IFERROR(I20/$I$67,0) -> 0.017184414 | K20: Sim | L20: Não | M20: Não | N20: Contrato permanece ativo cliente pagando 1.810,39 | O20: Não encontrou valor na solução
A21: CAPIVARY AGROPASTORIL LTDA | B21: 30010978 | C21: 30002051 | D21: Agrimanager ERP | E21: Downsell | F21: jan/26 | G21: 1 | H21: =SUMIFS(Base_Tratada!$H:$H,Base_Tratada!$A:$A,$A21,Base_Tratada!$G:$G,$D21) -> -1657.47 | I21: =-H21 -> 1657.47 | J21: =IFERROR(I21/$I$67,0) -> 0.015267451 | K21: Sim | L21: Sim | M21: Sim | N21: Terceirizou ADM e financeiro para a contabilidade, inicialmente permaneceriam com um usuário, por fim optaram por realizar o cancelamento | O21: Baixa adoção / não uso / falta de mão obra
A22: CARLOS ALBERTO MORESCO | B22: 20000027 | C22: 30001343 | D22: Vistra BI - PR | E22: Churn | F22: fev/26 | G22: 1 | H22: =SUMIFS(Base_Tratada!$H:$H,Base_Tratada!$A:$A,$A22,Base_Tratada!$G:$G,$D22) -> -1655.56 | I22: =-H22 -> 1655.56 | J22: =IFERROR(I22/$I$67,0) -> 0.015249858 | K22: Sim | L22: Sim | M22: Sim | N22: Restrições financeiras | O22: problemas financeiros
A23: BRUNO SANCHES TORO | B23: 30015024 | C23: 30004006 | D23: Aliare Cloud - PR | E23: Churn | F23: jun/26 | G23: 3 | H23: =SUMIFS(Base_Tratada!$H:$H,Base_Tratada!$A:$A,$A23,Base_Tratada!$G:$G,$D23) -> -1650.36 | I23: =-H23 -> 1650.36 | J23: =IFERROR(I23/$I$67,0) -> 0.015201959 | K23: Sim | L23: Sim | M23: Sim | N23: Problemas financeiros | O23: problemas financeiros
A24: OSVALDO HANISCH - I.E. 057.547.903 | B24: 10002290 | C24: 30001671 | D24: Agrimanager ERP | E24: Downsell | F24: jun/26 | G24: 1 | H24: =SUMIFS(Base_Tratada!$H:$H,Base_Tratada!$A:$A,$A24,Base_Tratada!$G:$G,$D24) -> -1484.86 | I24: =-H24 -> 1484.86 | J24: =IFERROR(I24/$I$67,0) -> 0.013677489 | L24: Sim | M24: Sim | N24: Reestruturação no quadro de colaboradores | O24: Falta de mão de obra / estrutura
A25: AGRO 100 COMERCIO DE PRODUTOS AGRICOLAS LTDA - EM RECUPERACAO | B25: 10001146 | C25: 10000135 | D25: Agrimanager ERP | E25: Churn | F25: mar/26 | G25: 1 | H25: =SUMIFS(Base_Tratada!$H:$H,Base_Tratada!$A:$A,$A25,Base_Tratada!$G:$G,$D25) -> -1375.16 | I25: =-H25 -> 1375.16 | J25: =IFERROR(I25/$I$67,0) -> 0.012667009 | L25: Sem informação | M25: Não | N25: Sem informação | O25: Sem relatório de churn
A26: FERNANDO CAVALHEIRO MACHADO I.E.29.439.136-3 | B26: 30008736 | C26: 30005481 | D26: Vistra BI - PR | E26: Downsell | F26: fev/26 | G26: 1 | H26: =SUMIFS(Base_Tratada!$H:$H,Base_Tratada!$A:$A,$A26,Base_Tratada!$G:$G,$D26) -> -1352.1 | I26: =-H26 -> 1352.1 | J26: =IFERROR(I26/$I$67,0) -> 0.012454597 | L26: Não | M26: Não | N26: Provável inadimplência, sem tratativa de churn localizada | O26: Sem relatório de churn
A27: MARIO PINTO DA SILVA | B27: 30020666 | C27: 30007174 | D27: My Farm ERP | E27: Churn | F27: jun/26 | G27: 1 | H27: =SUMIFS(Base_Tratada!$H:$H,Base_Tratada!$A:$A,$A27,Base_Tratada!$G:$G,$D27) -> -1327.99 | I27: =-H27 -> 1327.99 | J27: =IFERROR(I27/$I$67,0) -> 0.012232512 | K27: Sim | L27: Sim | M27: Sim | N27: Gap funcional: cliente de pecuária, My Farm não atendeu | O27: Gap funcional / limitação do produto
A28: FLAVIO FAEDO IE 11.508.239-5 | B28: 130 | C28: 30002569 | D28: My Farm ERP | E28: Churn | F28: fev/26 | G28: 1 | H28: =SUMIFS(Base_Tratada!$H:$H,Base_Tratada!$A:$A,$A28,Base_Tratada!$G:$G,$D28) -> -1201.82 | I28: =-H28 -> 1201.82 | J28: =IFERROR(I28/$I$67,0) -> 0.011070323 | K28: Sim | L28: Sim | M28: Sim | N28: Troca de ERP | O28: Falta de engajamento e recursos do produto
A29: ACASSIO TELES DE CASTRO | B29: 30017239 | C29: 30005439 | D29: My Farm ERP | E29: Churn | F29: jan/26 | G29: 1 | H29: =SUMIFS(Base_Tratada!$H:$H,Base_Tratada!$A:$A,$A29,Base_Tratada!$G:$G,$D29) -> -1200 | I29: =-H29 -> 1200 | J29: =IFERROR(I29/$I$67,0) -> 0.011053558 | K29: Sim | L29: Sim | M29: Sim | N29: Falta de mão de obra para operar o sistema | O29: Falta de mão de obra / estrutura
A30: S EPP AGRICOLA LTDA | B30: 30015247 | C30: 30001307 | D30: Vistra BI - PR | E30: Downsell | F30: fev/26 | G30: 1 | H30: =SUMIFS(Base_Tratada!$H:$H,Base_Tratada!$A:$A,$A30,Base_Tratada!$G:$G,$D30) -> -1178.13 | I30: =-H30 -> 1178.13 | J30: =IFERROR(I30/$I$67,0) -> 0.010852107 | L30: Não | M30: Não | N30: Ajuste financeiro pelo time de contratos | O30: Reajuste financeiro contratual
A31: ANDRE LUIZ COELHO GUILHERME | B31: 30016960 | C31: 30005242 | D31: My Farm ERP | E31: Churn | F31: mai/26 | G31: 1 | H31: =SUMIFS(Base_Tratada!$H:$H,Base_Tratada!$A:$A,$A31,Base_Tratada!$G:$G,$D31) -> -1073.29 | I31: =-H31 -> 1073.29 | J31: =IFERROR(I31/$I$67,0) -> 0.0098863947 | K31: Sim | L31: Sim | M31: Sim | N31: Falta de mão de obra para operar o sistema | O31: Falta de mão de obra / estrutura
A32: PEDRO ALCEU BACH | B32: 30019380 | C32: 30006286 | D32: My Farm ERP | E32: Churn | F32: jun/26 | G32: 1 | H32: =SUMIFS(Base_Tratada!$H:$H,Base_Tratada!$A:$A,$A32,Base_Tratada!$G:$G,$D32) -> -1070 | I32: =-H32 -> 1070 | J32: =IFERROR(I32/$I$67,0) -> 0.0098560895 | K32: Sim | L32: Sim | M32: Sim | N32: Cliente alega que o sistema não atende as demandas | O32: Recursos do produto
A33: THIAGO DE ALMEIDA | B33: 30011397 | C33: 30002281 | D33: My Farm ERP | E33: Churn | F33: jun/26 | G33: 1 | H33: =SUMIFS(Base_Tratada!$H:$H,Base_Tratada!$A:$A,$A33,Base_Tratada!$G:$G,$D33) -> -1067.58 | I33: =-H33 -> 1067.58 | J33: =IFERROR(I33/$I$67,0) -> 0.0098337982 | K33: Sim | L33: Sim (ressalva) | M33: Sem informação | N33: Solicitado pelo cliente em 08/2025 — baixa registrada em jun/26 | O33: Falta de mão de obra / estrutura
A34: LUCAS BOLOGNINI STRACCI | B34: 30016543 | C34: 30001182 | D34: Agrimanager ERP | E34: Churn | F34: jun/26 | G34: 9 | H34: =SUMIFS(Base_Tratada!$H:$H,Base_Tratada!$A:$A,$A34,Base_Tratada!$G:$G,$D34) -> -1040.32 | I34: =-H34 -> 1040.32 | J34: =IFERROR(I34/$I$67,0) -> 0.0095826982 | K34: Sim | L34: Sim | M34: Sim | N34: Cliente solicitou em 09/2025 - baixa registrada em 06/2026 | O34: Troca de ERP
A35: ROQUE CASSOL | B35: 30017104 | C35: 30005345 | D35: My Farm ERP | E35: Churn | F35: fev/26 | G35: 1 | H35: =SUMIFS(Base_Tratada!$H:$H,Base_Tratada!$A:$A,$A35,Base_Tratada!$G:$G,$D35) -> -1010.94 | I35: =-H35 -> 1010.94 | J35: =IFERROR(I35/$I$67,0) -> 0.0093120702 | K35: Sim | L35: Sim | M35: Sim | N35: Uso restrito a emissão de nota; passou para a contabilidade | O35: Migração para solução própria ou contábil
A36: FABIANO BERGOLI ZAMBERLAN IE:120114927-1 | B36: 30017436 | C36: 30005541 | D36: My Farm ERP | E36: Churn | F36: jun/26 | G36: 1 | H36: =SUMIFS(Base_Tratada!$H:$H,Base_Tratada!$A:$A,$A36,Base_Tratada!$G:$G,$D36) -> -963.73 | I36: =-H36 -> 963.73 | J36: =IFERROR(I36/$I$67,0) -> 0.0088772048 | K36: Sim | L36: Sim | M36: Sim | N36: Desengajado e usava planilhas no paralelo | O36: Falta de mão de obra / estrutura
A37: PAULO RICARDO SANTIN | B37: 30017209 | C37: 30005426 | D37: My Farm ERP | E37: Churn | F37: jun/26 | G37: 1 | H37: =SUMIFS(Base_Tratada!$H:$H,Base_Tratada!$A:$A,$A37,Base_Tratada!$G:$G,$D37) -> -937.62 | I37: =-H37 -> 937.62 | J37: =IFERROR(I37/$I$67,0) -> 0.0086366978 | K37: Sim | L37: Sim | M37: Sim | N37: Nunca usou o sistema | O37: Baixa adoção / não uso
A38: DONA EMA AGROPECUARIA E INDUSTRIAL LTDA | B38: 30013184 | C38: 30000891 | D38: Agrimanager ERP | E38: Downsell | F38: fev/26 | G38: 1 | H38: =SUMIFS(Base_Tratada!$H:$H,Base_Tratada!$A:$A,$A38,Base_Tratada!$G:$G,$D38) -> -884.96 | I38: =-H38 -> 884.96 | J38: =IFERROR(I38/$I$67,0) -> 0.0081516308 | L38: Sim | M38: Não | N38: Redução feita atravez de ticket 698079 | O38: Sem informação
A39: EDUARDO ZORZI - I.E. 13.322.258-6 | B39: 30010781 | C39: 30001903 | D39: Vistra BI - PR | E39: Downsell | F39: fev/26 | G39: 1 | H39: =SUMIFS(Base_Tratada!$H:$H,Base_Tratada!$A:$A,$A39,Base_Tratada!$G:$G,$D39) -> -865.52 | I39: =-H39 -> 865.52 | J39: =IFERROR(I39/$I$67,0) -> 0.0079725632 | L39: Sim | M39: Sim | N39: Não estavam utilizando | O39: Baixa adoção / não uso
A40: ADEMIR JOSE COMPARIM IE-28.523.221-5 | B40: 30012242 | C40: 30002927 | D40: My Farm ERP | E40: Churn | F40: jan/26 | G40: 1 | H40: =SUMIFS(Base_Tratada!$H:$H,Base_Tratada!$A:$A,$A40,Base_Tratada!$G:$G,$D40) -> -840.51 | I40: =-H40 -> 840.51 | J40: =IFERROR(I40/$I$67,0) -> 0.0077421886 | K40: Sim | L40: Sim | M40: Sim | N40: Não localizado historico CS, apenas informação do time de contratos de que recebeu a demanda do CS | O40: Falta de mão de obra / estrutura
A41: EVANDRO VILELA BARROS IE 11.331.859-6 | B41: 30014925 | C41: 30003941 | D41: My Farm ERP | E41: Churn | F41: mai/26 | G41: 1 | H41: =SUMIFS(Base_Tratada!$H:$H,Base_Tratada!$A:$A,$A41,Base_Tratada!$G:$G,$D41) -> -827.41 | I41: =-H41 -> 827.41 | J41: =IFERROR(I41/$I$67,0) -> 0.0076215206 | K41: Sim | L41: Sim | M41: Sim | N41: Falta de mão de obra para operar o sistema | O41: Troca de ERP
...

Sheet Analises
A1: ANALISES DE CHURN E DOWNSELL — Vertical Produtores Agricolas — YTD jan a jun/2026
A2: Todos os numeros abaixo sao calculados por formula a partir das abas Base_Tratada e Dados_Origem. Nada esta digitado a mao.
A4: 1. RESUMO EXECUTIVO
A5: Indicador | B5: Valor | C5: Leitura
A6: Perda bruta total (Churn + Downsell) | B6: =SUMIFS(Base_Tratada!$H$5:$H$93,Base_Tratada!$F$5:$F$93,"Churn")+SUMIFS(Base_Tratada!$H$5:$H$93,Base_Tratada!$F$5:$F$93,"Downsell") -> -108562.33 | C6: Soma com sinal da coluna Variacao nas 89 linhas filtradas.
A7: dos quais Churn | B7: =SUMIFS(Base_Tratada!$H$5:$H$93,Base_Tratada!$F$5:$F$93,"Churn") -> -54930.404 | C7: 50,6% da perda. Cliente/produto encerrado.
A8: dos quais Downsell | B8: =SUMIFS(Base_Tratada!$H$5:$H$93,Base_Tratada!$F$5:$F$93,"Downsell") -> -53631.922 | C8: 49,4% da perda. Reducao de escopo com o cliente ativo.
A9: Clientes distintos afetados | B9: =SUMPRODUCT((Base_Tratada!$A$5:$A$93<>"")/COUNTIF(Base_Tratada!$A$5:$A$93,Base_Tratada!$A$5:$A$93&"")) -> 58 | C9: 12,0% da base de ~484 clientes ativos foi tocada em 6 meses.
A10: Eventos unicos (cliente x produto x mes) | B10: =SUM(Base_Tratada!$K$5:$K$93) -> 64 | C10: A aba Consolidado tem 62 linhas porque dois pares tiveram evento em 2 meses.
A11: MRR medio mensal da base | B11: =AVERAGE(Dados_Origem!$I$5:$I$10) -> 1325505 | C11: Media das 6 competencias.
A12: Taxa de churn bruta mensal | B12: =-B6/6/B11 -> 0.013650435 | C12: Perda media mensal sobre o MRR medio.
A13: Taxa de churn bruta anualizada | B13: =1-(1-B12)^12 -> 0.15204992 | C13: Perda bruta anualizada da base. Referencia SaaS PME: 10% a 15% ao ano.
A14: NRR estimado no semestre | B14: =(Dados_Origem!$I$5+B6+Dados_Origem!$C$11+Dados_Origem!$D$11)/Dados_Origem!$I$5 -> 0.94506517 | C14: MRR de jan mais perdas, upsell e reajuste. Nao conta novos logos.
A15: Ticket medio jan/26 | B15: =Dados_Origem!$I$5/Dados_Origem!$J$5 -> 2821.0861 | C15: MRR dividido por clientes ativos.
A16: Ticket medio jun/26 | B16: =Dados_Origem!$I$10/Dados_Origem!$J$10 -> 2685.5939 | C16: Queda de 4,8% em 6 meses.
A17: Concentracao: top 3 linhas cliente x produto | B17: =(LARGE(Consolidado!$I$5:$I$66,1)+LARGE(Consolidado!$I$5:$I$66,2)+LARGE(Consolidado!$I$5:$I$66,3))/SUM(Consolidado!$I$5:$I$66) -> 0.33904736 | C17: Por cliente (somando produtos) o top 3 chega a 35,7% e o top 10 a 60,0%.
A19: 2. VALOR DE CHURN E DOWNSELL POR MES
A20: Mes | B20: Churn (R$) | C20: Downsell (R$) | D20: Total (R$) | E20: MRR base do mes | F20: % do MRR | G20: Eventos de Churn | H20: Eventos de Downsell
A21: jan/26 | B21: =SUMIFS(Base_Tratada!$H$5:$H$93,Base_Tratada!$E$5:$E$93,"2026-01",Base_Tratada!$F$5:$F$93,"Churn") -> -5119.17 | C21: =SUMIFS(Base_Tratada!$H$5:$H$93,Base_Tratada!$E$5:$E$93,"2026-01",Base_Tratada!$F$5:$F$93,"Downsell") -> -1693.5217 | D21: =B21+C21 -> -6812.6917 | E21: =Dados_Origem!$I$5 -> 1325910.5 | F21: =-D21/E21 -> 0.0051381235 | G21: =SUMIFS(Base_Tratada!$K$5:$K$93,Base_Tratada!$E$5:$E$93,"2026-01",Base_Tratada!$F$5:$F$93,"Churn") -> 5 | H21: =SUMIFS(Base_Tratada!$K$5:$K$93,Base_Tratada!$E$5:$E$93,"2026-01",Base_Tratada!$F$5:$F$93,"Downsell") -> 2
A22: fev/26 | B22: =SUMIFS(Base_Tratada!$H$5:$H$93,Base_Tratada!$E$5:$E$93,"2026-02",Base_Tratada!$F$5:$F$93,"Churn") -> -13233.29 | C22: =SUMIFS(Base_Tratada!$H$5:$H$93,Base_Tratada!$E$5:$E$93,"2026-02",Base_Tratada!$F$5:$F$93,"Downsell") -> -22881.82 | D22: =B22+C22 -> -36115.11 | E22: =Dados_Origem!$I$6 -> 1320291.6 | F22: =-D22/E22 -> 0.027353889 | G22: =SUMIFS(Base_Tratada!$K$5:$K$93,Base_Tratada!$E$5:$E$93,"2026-02",Base_Tratada!$F$5:$F$93,"Churn") -> 9 | H22: =SUMIFS(Base_Tratada!$K$5:$K$93,Base_Tratada!$E$5:$E$93,"2026-02",Base_Tratada!$F$5:$F$93,"Downsell") -> 8
A23: mar/26 | B23: =SUMIFS(Base_Tratada!$H$5:$H$93,Base_Tratada!$E$5:$E$93,"2026-03",Base_Tratada!$F$5:$F$93,"Churn") -> -4069.8698 | C23: =SUMIFS(Base_Tratada!$H$5:$H$93,Base_Tratada!$E$5:$E$93,"2026-03",Base_Tratada!$F$5:$F$93,"Downsell") -> -561.54 | D23: =B23+C23 -> -4631.4098 | E23: =Dados_Origem!$I$7 -> 1337681.5 | F23: =-D23/E23 -> 0.0034622664 | G23: =SUMIFS(Base_Tratada!$K$5:$K$93,Base_Tratada!$E$5:$E$93,"2026-03",Base_Tratada!$F$5:$F$93,"Churn") -> 4 | H23: =SUMIFS(Base_Tratada!$K$5:$K$93,Base_Tratada!$E$5:$E$93,"2026-03",Base_Tratada!$F$5:$F$93,"Downsell") -> 2
A24: abr/26 | B24: =SUMIFS(Base_Tratada!$H$5:$H$93,Base_Tratada!$E$5:$E$93,"2026-04",Base_Tratada!$F$5:$F$93,"Churn") -> -157.28 | C24: =SUMIFS(Base_Tratada!$H$5:$H$93,Base_Tratada!$E$5:$E$93,"2026-04",Base_Tratada!$F$5:$F$93,"Downsell") -> 0 | D24: =B24+C24 -> -157.28 | E24: =Dados_Origem!$I$8 -> 1340358.8 | F24: =-D24/E24 -> 0.00011734172 | G24: =SUMIFS(Base_Tratada!$K$5:$K$93,Base_Tratada!$E$5:$E$93,"2026-04",Base_Tratada!$F$5:$F$93,"Churn") -> 1 | H24: =SUMIFS(Base_Tratada!$K$5:$K$93,Base_Tratada!$E$5:$E$93,"2026-04",Base_Tratada!$F$5:$F$93,"Downsell") -> 0
A25: mai/26 | B25: =SUMIFS(Base_Tratada!$H$5:$H$93,Base_Tratada!$E$5:$E$93,"2026-05",Base_Tratada!$F$5:$F$93,"Churn") -> -13849.484 | C25: =SUMIFS(Base_Tratada!$H$5:$H$93,Base_Tratada!$E$5:$E$93,"2026-05",Base_Tratada!$F$5:$F$93,"Downsell") -> -12235.12 | D25: =B25+C25 -> -26084.604 | E25: =Dados_Origem!$I$9 -> 1328960.4 | F25: =-D25/E25 -> 0.019627827 | G25: =SUMIFS(Base_Tratada!$K$5:$K$93,Base_Tratada!$E$5:$E$93,"2026-05",Base_Tratada!$F$5:$F$93,"Churn") -> 8 | H25: =SUMIFS(Base_Tratada!$K$5:$K$93,Base_Tratada!$E$5:$E$93,"2026-05",Base_Tratada!$F$5:$F$93,"Downsell") -> 6
A26: jun/26 | B26: =SUMIFS(Base_Tratada!$H$5:$H$93,Base_Tratada!$E$5:$E$93,"2026-06",Base_Tratada!$F$5:$F$93,"Churn") -> -18501.31 | C26: =SUMIFS(Base_Tratada!$H$5:$H$93,Base_Tratada!$E$5:$E$93,"2026-06",Base_Tratada!$F$5:$F$93,"Downsell") -> -16259.92 | D26: =B26+C26 -> -34761.23 | E26: =Dados_Origem!$I$10 -> 1299827.5 | F26: =-D26/E26 -> 0.026742957 | G26: =SUMIFS(Base_Tratada!$K$5:$K$93,Base_Tratada!$E$5:$E$93,"2026-06",Base_Tratada!$F$5:$F$93,"Churn") -> 14 | H26: =SUMIFS(Base_Tratada!$K$5:$K$93,Base_Tratada!$E$5:$E$93,"2026-06",Base_Tratada!$F$5:$F$93,"Downsell") -> 5
A27: TOTAL | B27: =SUM(B21:B26) -> -54930.404 | C27: =SUM(C21:C26) -> -53631.922 | D27: =SUM(D21:D26) -> -108562.33 | E27: =AVERAGE(E21:E26) -> 1325505 | F27: =-D27/E27/6 -> 0.013650435 | G27: =SUM(G21:G26) -> 41 | H27: =SUM(H21:H26) -> 23
A29: 3. QUANTIDADE DE EVENTOS POR MES x PRODUTO (evento = cliente x produto x mes)
A30: 3.1 CHURN — quantidade de eventos
A31: Produto | B31: jan/26 | C31: fev/26 | D31: mar/26 | E31: abr/26 | F31: mai/26 | G31: jun/26 | H31: Total
A32: Agrimanager Algodoeira | B32: =SUMIFS(Base_Tratada!$K$5:$K$93,Base_Tratada!$E$5:$E$93,"2026-01",Base_Tratada!$F$5:$F$93,"Churn",Base_Tratada!$G$5:$G$93,$A32) -> 0 | C32: =SUMIFS(Base_Tratada!$K$5:$K$93,Base_Tratada!$E$5:$E$93,"2026-02",Base_Tratada!$F$5:$F$93,"Churn",Base_Tratada!$G$5:$G$93,$A32) -> 0 | D32: =SUMIFS(Base_Tratada!$K$5:$K$93,Base_Tratada!$E$5:$E$93,"2026-03",Base_Tratada!$F$5:$F$93,"Churn",Base_Tratada!$G$5:$G$93,$A32) -> 1 | E32: =SUMIFS(Base_Tratada!$K$5:$K$93,Base_Tratada!$E$5:$E$93,"2026-04",Base_Tratada!$F$5:$F$93,"Churn",Base_Tratada!$G$5:$G$93,$A32) -> 0 | F32: =SUMIFS(Base_Tratada!$K$5:$K$93,Base_Tratada!$E$5:$E$93,"2026-05",Base_Tratada!$F$5:$F$93,"Churn",Base_Tratada!$G$5:$G$93,$A32) -> 0 | G32: =SUMIFS(Base_Tratada!$K$5:$K$93,Base_Tratada!$E$5:$E$93,"2026-06",Base_Tratada!$F$5:$F$93,"Churn",Base_Tratada!$G$5:$G$93,$A32) -> 0 | H32: =SUM(B32:G32) -> 1
A33: Agrimanager Autorize | B33: =SUMIFS(Base_Tratada!$K$5:$K$93,Base_Tratada!$E$5:$E$93,"2026-01",Base_Tratada!$F$5:$F$93,"Churn",Base_Tratada!$G$5:$G$93,$A33) -> 0 | C33: =SUMIFS(Base_Tratada!$K$5:$K$93,Base_Tratada!$E$5:$E$93,"2026-02",Base_Tratada!$F$5:$F$93,"Churn",Base_Tratada!$G$5:$G$93,$A33) -> 0 | D33: =SUMIFS(Base_Tratada!$K$5:$K$93,Base_Tratada!$E$5:$E$93,"2026-03",Base_Tratada!$F$5:$F$93,"Churn",Base_Tratada!$G$5:$G$93,$A33) -> 0 | E33: =SUMIFS(Base_Tratada!$K$5:$K$93,Base_Tratada!$E$5:$E$93,"2026-04",Base_Tratada!$F$5:$F$93,"Churn",Base_Tratada!$G$5:$G$93,$A33) -> 1 | F33: =SUMIFS(Base_Tratada!$K$5:$K$93,Base_Tratada!$E$5:$E$93,"2026-05",Base_Tratada!$F$5:$F$93,"Churn",Base_Tratada!$G$5:$G$93,$A33) -> 0 | G33: =SUMIFS(Base_Tratada!$K$5:$K$93,Base_Tratada!$E$5:$E$93,"2026-06",Base_Tratada!$F$5:$F$93,"Churn",Base_Tratada!$G$5:$G$93,$A33) -> 1 | H33: =SUM(B33:G33) -> 2
A34: Agrimanager ERP | B34: =SUMIFS(Base_Tratada!$K$5:$K$93,Base_Tratada!$E$5:$E$93,"2026-01",Base_Tratada!$F$5:$F$93,"Churn",Base_Tratada!$G$5:$G$93,$A34) -> 0 | C34: =SUMIFS(Base_Tratada!$K$5:$K$93,Base_Tratada!$E$5:$E$93,"2026-02",Base_Tratada!$F$5:$F$93,"Churn",Base_Tratada!$G$5:$G$93,$A34) -> 2 | D34: =SUMIFS(Base_Tratada!$K$5:$K$93,Base_Tratada!$E$5:$E$93,"2026-03",Base_Tratada!$F$5:$F$93,"Churn",Base_Tratada!$G$5:$G$93,$A34) -> 1 | E34: =SUMIFS(Base_Tratada!$K$5:$K$93,Base_Tratada!$E$5:$E$93,"2026-04",Base_Tratada!$F$5:$F$93,"Churn",Base_Tratada!$G$5:$G$93,$A34) -> 0 | F34: =SUMIFS(Base_Tratada!$K$5:$K$93,Base_Tratada!$E$5:$E$93,"2026-05",Base_Tratada!$F$5:$F$93,"Churn",Base_Tratada!$G$5:$G$93,$A34) -> 2 | G34: =SUMIFS(Base_Tratada!$K$5:$K$93,Base_Tratada!$E$5:$E$93,"2026-06",Base_Tratada!$F$5:$F$93,"Churn",Base_Tratada!$G$5:$G$93,$A34) -> 4 | H34: =SUM(B34:G34) -> 9
A35: Aliare Cloud - PR | B35: =SUMIFS(Base_Tratada!$K$5:$K$93,Base_Tratada!$E$5:$E$93,"2026-01",Base_Tratada!$F$5:$F$93,"Churn",Base_Tratada!$G$5:$G$93,$A35) -> 1 | C35: =SUMIFS(Base_Tratada!$K$5:$K$93,Base_Tratada!$E$5:$E$93,"2026-02",Base_Tratada!$F$5:$F$93,"Churn",Base_Tratada!$G$5:$G$93,$A35) -> 0 | D35: =SUMIFS(Base_Tratada!$K$5:$K$93,Base_Tratada!$E$5:$E$93,"2026-03",Base_Tratada!$F$5:$F$93,"Churn",Base_Tratada!$G$5:$G$93,$A35) -> 0 | E35: =SUMIFS(Base_Tratada!$K$5:$K$93,Base_Tratada!$E$5:$E$93,"2026-04",Base_Tratada!$F$5:$F$93,"Churn",Base_Tratada!$G$5:$G$93,$A35) -> 0 | F35: =SUMIFS(Base_Tratada!$K$5:$K$93,Base_Tratada!$E$5:$E$93,"2026-05",Base_Tratada!$F$5:$F$93,"Churn",Base_Tratada!$G$5:$G$93,$A35) -> 2 | G35: =SUMIFS(Base_Tratada!$K$5:$K$93,Base_Tratada!$E$5:$E$93,"2026-06",Base_Tratada!$F$5:$F$93,"Churn",Base_Tratada!$G$5:$G$93,$A35) -> 1 | H35: =SUM(B35:G35) -> 4
A36: My Farm ERP | B36: =SUMIFS(Base_Tratada!$K$5:$K$93,Base_Tratada!$E$5:$E$93,"2026-01",Base_Tratada!$F$5:$F$93,"Churn",Base_Tratada!$G$5:$G$93,$A36) -> 4 | C36: =SUMIFS(Base_Tratada!$K$5:$K$93,Base_Tratada!$E$5:$E$93,"2026-02",Base_Tratada!$F$5:$F$93,"Churn",Base_Tratada!$G$5:$G$93,$A36) -> 4 | D36: =SUMIFS(Base_Tratada!$K$5:$K$93,Base_Tratada!$E$5:$E$93,"2026-03",Base_Tratada!$F$5:$F$93,"Churn",Base_Tratada!$G$5:$G$93,$A36) -> 1 | E36: =SUMIFS(Base_Tratada!$K$5:$K$93,Base_Tratada!$E$5:$E$93,"2026-04",Base_Tratada!$F$5:$F$93,"Churn",Base_Tratada!$G$5:$G$93,$A36) -> 0 | F36: =SUMIFS(Base_Tratada!$K$5:$K$93,Base_Tratada!$E$5:$E$93,"2026-05",Base_Tratada!$F$5:$F$93,"Churn",Base_Tratada!$G$5:$G$93,$A36) -> 4 | G36: =SUMIFS(Base_Tratada!$K$5:$K$93,Base_Tratada!$E$5:$E$93,"2026-06",Base_Tratada!$F$5:$F$93,"Churn",Base_Tratada!$G$5:$G$93,$A36) -> 8 | H36: =SUM(B36:G36) -> 21
A37: Vistra BI - PR | B37: =SUMIFS(Base_Tratada!$K$5:$K$93,Base_Tratada!$E$5:$E$93,"2026-01",Base_Tratada!$F$5:$F$93,"Churn",Base_Tratada!$G$5:$G$93,$A37) -> 0 | C37: =SUMIFS(Base_Tratada!$K$5:$K$93,Base_Tratada!$E$5:$E$93,"2026-02",Base_Tratada!$F$5:$F$93,"Churn",Base_Tratada!$G$5:$G$93,$A37) -> 3 | D37: =SUMIFS(Base_Tratada!$K$5:$K$93,Base_Tratada!$E$5:$E$93,"2026-03",Base_Tratada!$F$5:$F$93,"Churn",Base_Tratada!$G$5:$G$93,$A37) -> 1 | E37: =SUMIFS(Base_Tratada!$K$5:$K$93,Base_Tratada!$E$5:$E$93,"2026-04",Base_Tratada!$F$5:$F$93,"Churn",Base_Tratada!$G$5:$G$93,$A37) -> 0 | F37: =SUMIFS(Base_Tratada!$K$5:$K$93,Base_Tratada!$E$5:$E$93,"2026-05",Base_Tratada!$F$5:$F$93,"Churn",Base_Tratada!$G$5:$G$93,$A37) -> 0 | G37: =SUMIFS(Base_Tratada!$K$5:$K$93,Base_Tratada!$E$5:$E$93,"2026-06",Base_Tratada!$F$5:$F$93,"Churn",Base_Tratada!$G$5:$G$93,$A37) -> 0 | H37: =SUM(B37:G37) -> 4
A38: TOTAL | B38: =SUM(B32:B37) -> 5 | C38: =SUM(C32:C37) -> 9 | D38: =SUM(D32:D37) -> 4 | E38: =SUM(E32:E37) -> 1 | F38: =SUM(F32:F37) -> 8 | G38: =SUM(G32:G37) -> 14 | H38: =SUM(H32:H37) -> 41
A39: 3.2 DOWNSELL — quantidade de eventos
A40: Produto | B40: jan/26 | C40: fev/26 | D40: mar/26 | E40: abr/26 | F40: mai/26 | G40: jun/26 | H40: Total
A41: Agrimanager Algodoeira | B41: =SUMIFS(Base_Tratada!$K$5:$K$93,Base_Tratada!$E$5:$E$93,"2026-01",Base_Tratada!$F$5:$F$93,"Downsell",Base_Tratada!$G$5:$G$93,$A41) -> 0 | C41: =SUMIFS(Base_Tratada!$K$5:$K$93,Base_Tratada!$E$5:$E$93,"2026-02",Base_Tratada!$F$5:$F$93,"Downsell",Base_Tratada!$G$5:$G$93,$A41) -> 0 | D41: =SUMIFS(Base_Tratada!$K$5:$K$93,Base_Tratada!$E$5:$E$93,"2026-03",Base_Tratada!$F$5:$F$93,"Downsell",Base_Tratada!$G$5:$G$93,$A41) -> 0 | E41: =SUMIFS(Base_Tratada!$K$5:$K$93,Base_Tratada!$E$5:$E$93,"2026-04",Base_Tratada!$F$5:$F$93,"Downsell",Base_Tratada!$G$5:$G$93,$A41) -> 0 | F41: =SUMIFS(Base_Tratada!$K$5:$K$93,Base_Tratada!$E$5:$E$93,"2026-05",Base_Tratada!$F$5:$F$93,"Downsell",Base_Tratada!$G$5:$G$93,$A41) -> 0 | G41: =SUMIFS(Base_Tratada!$K$5:$K$93,Base_Tratada!$E$5:$E$93,"2026-06",Base_Tratada!$F$5:$F$93,"Downsell",Base_Tratada!$G$5:$G$93,$A41) -> 0 | H41: =SUM(B41:G41) -> 0
A42: Agrimanager Autorize | B42: =SUMIFS(Base_Tratada!$K$5:$K$93,Base_Tratada!$E$5:$E$93,"2026-01",Base_Tratada!$F$5:$F$93,"Downsell",Base_Tratada!$G$5:$G$93,$A42) -> 0 | C42: =SUMIFS(Base_Tratada!$K$5:$K$93,Base_Tratada!$E$5:$E$93,"2026-02",Base_Tratada!$F$5:$F$93,"Downsell",Base_Tratada!$G$5:$G$93,$A42) -> 0 | D42: =SUMIFS(Base_Tratada!$K$5:$K$93,Base_Tratada!$E$5:$E$93,"2026-03",Base_Tratada!$F$5:$F$93,"Downsell",Base_Tratada!$G$5:$G$93,$A42) -> 1 | E42: =SUMIFS(Base_Tratada!$K$5:$K$93,Base_Tratada!$E$5:$E$93,"2026-04",Base_Tratada!$F$5:$F$93,"Downsell",Base_Tratada!$G$5:$G$93,$A42) -> 0 | F42: =SUMIFS(Base_Tratada!$K$5:$K$93,Base_Tratada!$E$5:$E$93,"2026-05",Base_Tratada!$F$5:$F$93,"Downsell",Base_Tratada!$G$5:$G$93,$A42) -> 0 | G42: =SUMIFS(Base_Tratada!$K$5:$K$93,Base_Tratada!$E$5:$E$93,"2026-06",Base_Tratada!$F$5:$F$93,"Downsell",Base_Tratada!$G$5:$G$93,$A42) -> 2 | H42: =SUM(B42:G42) -> 3
A43: Agrimanager ERP | B43: =SUMIFS(Base_Tratada!$K$5:$K$93,Base_Tratada!$E$5:$E$93,"2026-01",Base_Tratada!$F$5:$F$93,"Downsell",Base_Tratada!$G$5:$G$93,$A43) -> 1 | C43: =SUMIFS(Base_Tratada!$K$5:$K$93,Base_Tratada!$E$5:$E$93,"2026-02",Base_Tratada!$F$5:$F$93,"Downsell",Base_Tratada!$G$5:$G$93,$A43) -> 3 | D43: =SUMIFS(Base_Tratada!$K$5:$K$93,Base_Tratada!$E$5:$E$93,"2026-03",Base_Tratada!$F$5:$F$93,"Downsell",Base_Tratada!$G$5:$G$93,$A43) -> 1 | E43: =SUMIFS(Base_Tratada!$K$5:$K$93,Base_Tratada!$E$5:$E$93,"2026-04",Base_Tratada!$F$5:$F$93,"Downsell",Base_Tratada!$G$5:$G$93,$A43) -> 0 | F43: =SUMIFS(Base_Tratada!$K$5:$K$93,Base_Tratada!$E$5:$E$93,"2026-05",Base_Tratada!$F$5:$F$93,"Downsell",Base_Tratada!$G$5:$G$93,$A43) -> 3 | G43: =SUMIFS(Base_Tratada!$K$5:$K$93,Base_Tratada!$E$5:$E$93,"2026-06",Base_Tratada!$F$5:$F$93,"Downsell",Base_Tratada!$G$5:$G$93,$A43) -> 3 | H43: =SUM(B43:G43) -> 11
...

Sheet Base_Tratada
A1: BASE TRATADA — 89 linhas originais com STATUS = Churn ou Downsell
A2: Linhas exatamente como na origem, sem alteração de valores. Colunas E, J e K são derivadas para permitir as fórmulas das outras abas.
A4: Cliente | B4: Cód. Cliente | C4: Contrato | D4: Competência | E4: Mês | F4: Status | G4: Produto | H4: Variação (R$) | I4: Valor faturado (R$) | J4: Tipo de linha | K4: Evento único
A5: 3SB PRODUTOS AGRICOLAS S.A. | B5: 30007727 | C5: 30000677 | D5: 46054 | E5: 2026-02 | F5: Churn | G5: Agrimanager ERP | H5: -3861.97 | I5: 0 | J5: Perda de receita (-) | K5: 1
A6: 3SB PRODUTOS AGRICOLAS S.A. | B6: 30007727 | C6: 30000677 | D6: 46054 | E6: 2026-02 | F6: Churn | G6: Agrimanager ERP | H6: -386.1 | I6: 0 | J6: Perda de receita (-) | K6: 0
A7: 3SB PRODUTOS AGRICOLAS S.A. | B7: 30007727 | C7: 30000677 | D7: 46054 | E7: 2026-02 | F7: Churn | G7: Agrimanager ERP | H7: 4248.07 | I7: 0 | J7: Estorno de linha negativa (+) | K7: 0
A8: 3SB PRODUTOS AGRICOLAS S.A. | B8: 30007727 | C8: 30000677 | D8: 46054 | E8: 2026-02 | F8: Churn | G8: Agrimanager ERP | H8: -3849.64 | I8: 0 | J8: Perda de receita (-) | K8: 0
A9: 3SB PRODUTOS AGRICOLAS S.A. | B9: 30007727 | C9: 30000677 | D9: 46054 | E9: 2026-02 | F9: Churn | G9: Agrimanager ERP | H9: -320.82 | I9: 0 | J9: Perda de receita (-) | K9: 0
A10: ACASSIO TELES DE CASTRO | B10: 30017239 | C10: 30005439 | D10: 46023 | E10: 2026-01 | F10: Churn | G10: My Farm ERP | H10: -1200 | I10: 0 | J10: Perda de receita (-) | K10: 1
A11: ADEMIR JOSE COMPARIM IE-28.523.221-5 | B11: 30012242 | C11: 30002927 | D11: 46023 | E11: 2026-01 | F11: Churn | G11: My Farm ERP | H11: -840.51 | I11: 0 | J11: Perda de receita (-) | K11: 1
A12: ADRIANO XAVIER PIVETTA E OUTROS I.E 13.438.585-3 | B12: 30011394 | C12: 30002303 | D12: 46082 | E12: 2026-03 | F12: Downsell | G12: Agrimanager Autorize | H12: 0 | I12: 0 | J12: Evento sem impacto financeiro | K12: 1
A13: AGRO 100 COMERCIO DE PRODUTOS AGRICOLAS LTDA - EM RECUPERACAO | B13: 10001146 | C13: 10000135 | D13: 46082 | E13: 2026-03 | F13: Churn | G13: Agrimanager ERP | H13: -1375.16 | I13: 0 | J13: Perda de receita (-) | K13: 1
A14: ANDRE LUIZ COELHO GUILHERME | B14: 30016960 | C14: 30005242 | D14: 46143 | E14: 2026-05 | F14: Churn | G14: My Farm ERP | H14: -1073.29 | I14: 0 | J14: Perda de receita (-) | K14: 1
A15: ANTONIO MIGUEL WEBER DOS SANTOS I.E. 13.294.586-0 | B15: 30010080 | C15: 30001646 | D15: 46113 | E15: 2026-04 | F15: Churn | G15: Agrimanager Autorize | H15: -157.28 | I15: -157.28 | J15: Perda de receita (-) | K15: 1
A16: BRUNO RODRIGUES CAPPELLESSO | B16: 30011293 | C16: 30002239 | D16: 46023 | E16: 2026-01 | F16: Downsell | G16: My Farm ERP | H16: -36.051667 | I16: -36.051667 | J16: Perda de receita (-) | K16: 1
A17: BRUNO SANCHES TORO | B17: 30015024 | C17: 30004006 | D17: 46174 | E17: 2026-06 | F17: Churn | G17: Agrimanager ERP | H17: -2326.2 | J17: Perda de receita (-) | K17: 1
A18: BRUNO SANCHES TORO | B18: 30015024 | C18: 30004006 | D18: 46174 | E18: 2026-06 | F18: Churn | G18: Agrimanager ERP | H18: -932.27 | J18: Perda de receita (-) | K18: 0
A19: BRUNO SANCHES TORO | B19: 30015024 | C19: 30004006 | D19: 46174 | E19: 2026-06 | F19: Churn | G19: Agrimanager ERP | H19: -752.22 | J19: Perda de receita (-) | K19: 0
A20: BRUNO SANCHES TORO | B20: 30015024 | C20: 30004006 | D20: 46174 | E20: 2026-06 | F20: Churn | G20: Aliare Cloud - PR | H20: -887.6 | J20: Perda de receita (-) | K20: 1
A21: BRUNO SANCHES TORO | B21: 30015024 | C21: 30004006 | D21: 46174 | E21: 2026-06 | F21: Churn | G21: Aliare Cloud - PR | H21: -355.72 | J21: Perda de receita (-) | K21: 0
A22: BRUNO SANCHES TORO | B22: 30015024 | C22: 30004006 | D22: 46174 | E22: 2026-06 | F22: Churn | G22: Aliare Cloud - PR | H22: -407.04 | J22: Perda de receita (-) | K22: 0
A23: CAPIVARY AGROPASTORIL LTDA | B23: 30010978 | C23: 30002051 | D23: 46023 | E23: 2026-01 | F23: Downsell | G23: Agrimanager ERP | H23: -1657.47 | I23: -1657.47 | J23: Perda de receita (-) | K23: 1
A24: CARLOS ALBERTO MORESCO | B24: 20000027 | C24: 30001343 | D24: 46054 | E24: 2026-02 | F24: Churn | G24: Vistra BI - PR | H24: -1655.56 | I24: -1655.56 | J24: Perda de receita (-) | K24: 1
A25: CARLOS FERNANDO DA SILVEIRA BUENO | B25: 30017285 | C25: 30005453 | D25: 46023 | E25: 2026-01 | F25: Churn | G25: My Farm ERP | H25: -583.33 | I25: 0 | J25: Perda de receita (-) | K25: 1
A26: CLAUDIO AUGUSTO DINIZ - I.E. 13.235.367-9 | B26: 30009772 | C26: 30001556 | D26: 46143 | E26: 2026-05 | F26: Churn | G26: Agrimanager ERP | H26: -1950.8 | I26: 0 | J26: Perda de receita (-) | K26: 1
A27: CLAUDIO AUGUSTO DINIZ - I.E. 13.235.367-9 | B27: 30009772 | C27: 30001556 | D27: 46143 | E27: 2026-05 | F27: Churn | G27: Agrimanager ERP | H27: -1457.6 | I27: 0 | J27: Perda de receita (-) | K27: 0
A28: CLODOVEU FRANCIOSI IE 133535746 | B28: 30006916 | C28: 30001424 | D28: 46082 | E28: 2026-03 | F28: Churn | G28: Agrimanager Algodoeira | H28: -1926.9898 | I28: -1926.9898 | J28: Perda de receita (-) | K28: 1
A29: CLODOVEU FRANCIOSI IE 133535746 | B29: 30006916 | C29: 30001424 | D29: 46174 | E29: 2026-06 | F29: Downsell | G29: Agrimanager ERP | H29: -13701.65 | I29: -13701.65 | J29: Perda de receita (-) | K29: 1
A30: CORNELIO ADRIANO SANDERS E OUTROS | B30: 20000043 | C30: 30000717 | D30: 46174 | E30: 2026-06 | F30: Downsell | G30: Agrimanager ERP | H30: -514.72 | I30: -514.72 | J30: Perda de receita (-) | K30: 1
A31: DONA EMA AGROPECUARIA E INDUSTRIAL LTDA | B31: 30013184 | C31: 30000891 | D31: 46054 | E31: 2026-02 | F31: Downsell | G31: Agrimanager ERP | H31: -884.96 | I31: -884.96 | J31: Perda de receita (-) | K31: 1
A32: EDIANA EDITH BOERI IE: 126447373 | B32: 30013092 | C32: 30003274 | D32: 46143 | E32: 2026-05 | F32: Downsell | G32: My Farm ERP | H32: -65.3 | I32: -65.3 | J32: Perda de receita (-) | K32: 1
A33: EDUARDO ZORZI - I.E. 13.322.258-6 | B33: 30010781 | C33: 30001903 | D33: 46054 | E33: 2026-02 | F33: Downsell | G33: Vistra BI - PR | H33: -865.52 | I33: -865.52 | J33: Perda de receita (-) | K33: 1
A34: ELIANA GASPARINI TESTA IE 111876893 | B34: 30018091 | C34: 30005902 | D34: 46054 | E34: 2026-02 | F34: Churn | G34: My Farm ERP | H34: -480 | I34: 0 | J34: Perda de receita (-) | K34: 1
A35: EVANDRO VILELA BARROS IE 11.331.859-6 | B35: 30014925 | C35: 30003941 | D35: 46143 | E35: 2026-05 | F35: Churn | G35: My Farm ERP | H35: -827.41 | I35: 0 | J35: Perda de receita (-) | K35: 1
A36: FABIANO BERGOLI ZAMBERLAN IE:120114927-1 | B36: 30017436 | C36: 30005541 | D36: 46174 | E36: 2026-06 | F36: Churn | G36: My Farm ERP | H36: -963.73 | J36: Perda de receita (-) | K36: 1
A37: FERNANDO CAVALHEIRO MACHADO I.E.29.439.136-3 | B37: 30008736 | C37: 30005481 | D37: 46054 | E37: 2026-02 | F37: Downsell | G37: Vistra BI - PR | H37: -1352.1 | I37: -1352.1 | J37: Perda de receita (-) | K37: 1
A38: FLAVIO FAEDO IE 11.508.239-5 | B38: 130 | C38: 30002569 | D38: 46054 | E38: 2026-02 | F38: Churn | G38: My Farm ERP | H38: -1201.82 | I38: 0 | J38: Perda de receita (-) | K38: 1
A39: GERALDO AUGUSTO MARTINS TEIXEIRA IE 37260520019 | B39: 30015743 | C39: 30005853 | D39: 46082 | E39: 2026-03 | F39: Churn | G39: My Farm ERP | H39: -320 | I39: 0 | J39: Perda de receita (-) | K39: 1
A40: GUILHERME DE ARAUJO PREDIGER | C40: 30007398 | D40: 46174 | E40: 2026-06 | F40: Churn | G40: My Farm ERP | H40: -621.26 | J40: Perda de receita (-) | K40: 1
A41: JORGE AUGUSTO BARRAGANA BRAZEIRO | B41: 30016118 | C41: 30004747 | D41: 46082 | E41: 2026-03 | F41: Churn | G41: Vistra BI - PR | H41: -447.72 | I41: 0 | J41: Perda de receita (-) | K41: 1
...

Sheet Dados_Origem
A1: DADOS DE ORIGEM — movimentação completa do MRR e base faturada
A2: Valores em AZUL são inputs extraídos direto do arquivo original (soma da coluna Variacao por competência x STATUS, e soma da coluna valor por competência). Não são calculados aqui.
A4: Mês | B4: NewMRR | C4: Upsell | D4: Reajuste | E4: Ajustes | F4: Sem alteração | G4: Downsell | H4: Churn | I4: MRR base faturado | J4: Clientes na base
A5: jan/26 | B5: 4815.29 | C5: 3301.64 | D5: 225.325 | E5: -4985.29 | F5: 0.18166667 | G5: -1693.5217 | H5: -5119.17 | I5: 1325910.5 | J5: 470
A6: fev/26 | B6: 13662.66 | C6: 10796.99 | D6: 1889.3692 | E6: 0 | F6: 0.16 | G6: -22881.82 | H6: -13233.29 | I6: 1320291.6 | J6: 479
A7: mar/26 | B7: 14361.57 | C7: 7665.44 | D7: 813.3025 | E7: -818.96 | F7: -2.5579538e-13 | G7: -561.54 | H7: -4069.8698 | I7: 1337681.5 | J7: 486
A8: abr/26 | B8: 2279.96 | C8: 837.9 | D8: -339.75833 | E8: 56.41 | F8: 0.02 | G8: 0 | H8: -157.28 | I8: 1340358.8 | J8: 484
A9: mai/26 | B9: 6849.4 | C9: 504.4 | D9: 6940.9252 | E9: 391.44 | F9: 0 | G9: -12235.12 | H9: -13849.484 | I9: 1328960.4 | J9: 487
A10: jun/26 | B10: 2931.66 | C10: 3088.12 | D10: 0 | E10: -391.44 | F10: 0 | G10: -16259.92 | H10: -18501.31 | I10: 1299827.5 | J10: 484
A11: TOTAL YTD | B11: =SUM(B5:B10) -> 44900.54 | C11: =SUM(C5:C10) -> 26194.49 | D11: =SUM(D5:D10) -> 9529.1635 | E11: =SUM(E5:E10) -> -5747.84 | F11: =SUM(F5:F10) -> 0.36166667 | G11: =SUM(G5:G10) -> -53631.922 | H11: =SUM(H5:H10) -> -54930.404 | I11: =SUM(I5:I10) -> 7953030.2
A12: Fonte: Produtor__Rural_-_Lista_YTD_06-2026.xlsx (aba Planilha1). MRR base = soma da coluna "valor" na competência; linhas com valor vazio contam como zero (jan/26 tem 493 linhas vazias, mai/26 tem 276 — ver Notas).
